<?xml version="1.0" encoding="UTF-8"?>
<!-- This URDF was automatically created by SolidWorks to URDF Exporter! Originally created by
Stephen Brawner (brawner@gmail.com) 
     Commit Version: 1.5.1-0-g916b5db  Build Version: 1.5.7152.31018
     For more information, please see http://wiki.ros.org/sw_urdf_exporter -->

<robot name="segwayrmp_urdf" xmlns:xacro="http://ros.org/wiki/xacro">
  <xacro:arg name="robot_namespace" default="/" />
  <xacro:include filename="$(find segwayrmp_description)/urdf/segwayrmp_xacro.xacro" />
  <!-- <xacro:include filename="$(find segwayrmp_description)/urdf/segwayrmp_steering.xacro" /> -->
  <xacro:include filename="$(find segwayrmp_description)/urdf/segwayrmp_ackerman.gazebo" />

  <!-- Define robot constants -->
  <xacro:property name="base_length" value="0.18" />
  <xacro:property name="base_width" value="0.61" />
  <xacro:property name="base_height" value="0.09" />

  <xacro:property name="wheel_length" value="0.05" />
  <xacro:property name="wheel_radius" value="0.1" />

  <!-- Robot Base -->
  <link name="base_link">
    <inertial>
      <origin
        xyz="0 0.2 0.19"
        rpy="0 0 0" />
      <mass value="12.0" />
      <inertia ixx="0.0296962022350776" ixy="0" ixz="0"
        iyy="0.00646533575042488" iyz="0" izz="0.0331663553221158" />
    </inertial>
    <visual>
      <origin xyz="0 0.24 0.21" rpy="0 0 0" />
      <geometry>
        <box size="${base_length} ${base_width} ${base_height}" />
      </geometry>
      <material name="">
        <color rgba="0.792156862745098 0.819607843137255 0.933333333333333 1" />
      </material>
    </visual>
    <collision>
      <origin xyz="0 0.24 0.21" rpy="0 0 0" />
      <geometry>
        <box size="${base_length} ${base_width} ${base_height}" />
      </geometry>
    </collision>
  </link>

  <!-- Sensors -->
  <xacro:segwayrmp_laser parent_prefix="base_link" frame_prefix="laser">
    <origin xyz="0 0.46 0.26" rpy="0 0 0" />
  </xacro:segwayrmp_laser>

  <xacro:segwayrmp_imu parent_prefix="base_link" frame_prefix="imu">
    <origin xyz="0 0 0.14" rpy="0 0 0" />
  </xacro:segwayrmp_imu>

  <!-- Steering -->
  <link name="steering_wheel_link">
    <inertial>
      <origin
        xyz="0 0 0"
        rpy="0 0 0" />
      <mass value="0.3" />
      <inertia ixx="0.0008778" ixy="0.0" ixz="0.0" iyy="0.00011879" iyz="0.0" izz="0.0008778" />
    </inertial>
    <visual>
      <origin xyz="0 0 0" rpy="0 0 0" />
      <geometry>
        <box size="0.01 0.01 0.01" />
      </geometry>
      <material name="">
        <color rgba="0.792156862745098 0.819607843137255 0.933333333333333 1" />
      </material>
    </visual>
    <collision>
      <origin xyz="0 0 0" rpy="0 0 0" />
      <geometry>
        <box size="0.01 0.01 0.01" />
      </geometry>
    </collision>
  </link>
  <joint name="steering_wheel_joint" type="revolute">
    <origin xyz="0 0.46 0.15" rpy="1.5708 0 0" />
    <parent link="base_link" />
    <child link="steering_wheel_link" />
    <axis xyz="0 1 0" />
    <limit lower="-0.36" upper="0.36" effort="5" velocity="1.0" />
    <dynamics damping="0.1" friction="1.0" />
  </joint>

  <link name="front_wheels_link">
    <inertial>
      <origin
        xyz="0 0 0"
        rpy="0 0 1.57" />
      <mass value="0.379124506048444" />
      <inertia ixx="0.00001697" ixy="0.0" ixz="0.0" iyy="0.01254" iyz="0.0" izz="0.01254" />
    </inertial>
    <visual>
      <origin xyz="0 0 0" rpy="0 1.57 0" />
      <geometry>
        <cylinder radius="0.07" length="0.45" />
      </geometry>
      <material name="">
        <color rgba="0.792156862745098 0.819607843137255 0.933333333333333 1" />
      </material>
    </visual>
    <collision>
      <origin xyz="0 0 0" rpy="0 1.57 0" />
      <geometry>
        <cylinder radius="0.07" length="0.45" />
      </geometry>
    </collision>
  </link>
  <joint name="front_wheels_joint" type="continuous">
    <origin
      xyz="0 -0.06 0"
      rpy="0 0 0" />
    <parent link="steering_wheel_link" />
    <child link="front_wheels_link" />
    <axis xyz="-1 0 0" />
    <dynamics damping="0.1" friction="1.0" />
  </joint>

  <!-- Wheels -->
  <link name="front_left_wheel_link">
    <inertial>
      <origin
        xyz="-0.175 0 0"
        rpy="0 0 0" />
      <mass value="0.379124506048444" />
      <inertia
        ixx="0.00135623331658277"
        ixy="-2.05858146537997E-08"
        ixz="2.75425144310775E-07"
        iyy="0.00074553860560749"
        iyz="-2.05160697747808E-08"
        izz="0.000744863292198173" />
    </inertial>
    <visual>
      <origin
        xyz="-0.165 0 0"
        rpy="0 1.57 0" />
      <geometry>
        <cylinder radius="${wheel_radius}" length="${wheel_length}" />
      </geometry>
      <material name="">
        <color rgba="0.792156862745098 0.819607843137255 0.933333333333333 1" />
      </material>
    </visual>
    <collision>
      <origin
        xyz="-0.165 0 0"
        rpy="0 1.57 0" />
      <geometry>
        <cylinder radius="${wheel_radius}" length="${wheel_length}" />
      </geometry>
    </collision>
  </link>
  <joint name="front_left_wheel_joint" type="fixed">
    <origin
      xyz="-0.1 0 0"
      rpy="3.14 0 0" />
    <parent link="front_wheels_link" />
    <child link="front_left_wheel_link" />
    <!-- <axis xyz="1 0 0" /> -->
    <dynamics damping="0.1" friction="1.0" />
  </joint>

  <link name="front_right_wheel_link">
    <inertial>
      <origin
        xyz="0.175 0 0"
        rpy="0 1.57 0" />
      <mass value="0.379124506048444" />
      <inertia
        ixx="0.00135623331658277"
        ixy="-2.05858146537997E-08"
        ixz="2.75425144310775E-07"
        iyy="0.00074553860560749"
        iyz="-2.05160697747808E-08"
        izz="0.000744863292198173" />
    </inertial>
    <visual>
      <origin
        xyz="0.165 0 0"
        rpy="0 1.57 0" />
      <geometry>
        <cylinder radius="${wheel_radius}" length="${wheel_length}" />
      </geometry>
      <material name="">
        <color rgba="0.792156862745098 0.819607843137255 0.933333333333333 1" />
      </material>
    </visual>
    <collision>
      <origin
        xyz="0.165 0 0"
        rpy="0 1.57 0" />
      <geometry>
        <cylinder radius="${wheel_radius}" length="${wheel_length}" />
      </geometry>
    </collision>
  </link>
  <joint name="front_right_wheel_joint" type="fixed">
    <origin
      xyz="0.1 0 0"
      rpy="1.57 3.1416 3.1416" />
    <parent link="front_wheels_link" />
    <child link="front_right_wheel_link" />
    <!-- <axis xyz="1 0 0" /> -->
    <dynamics damping="0.1" friction="1.0" />
  </joint>

  <link name="rear_left_wheel_link">
    <inertial>
      <origin
        xyz="-0.175 4.72112875317676E-05 9.00201436271342E-06"
        rpy="0 0 0" />
      <mass value="0.379124506048444" />
      <inertia
        ixx="0.00135623331658277"
        ixy="-2.05858146537997E-08"
        ixz="2.75425144310775E-07"
        iyy="0.00074553860560749"
        iyz="-2.05160697747808E-08"
        izz="0.000744863292198173" />
    </inertial>
    <visual>
      <origin
        xyz="-0.165 0 0"
        rpy="0 1.57 0" />
      <geometry>
        <cylinder radius="${wheel_radius}" length="${wheel_length}" />
      </geometry>
      <material name="">
        <color rgba="0.792156862745098 0.819607843137255 0.933333333333333 1" />
      </material>
    </visual>
    <collision>
      <origin
        xyz="-0.165 0 0"
        rpy="0 1.57 0" />
      <geometry>
        <cylinder radius="${wheel_radius}" length="${wheel_length}" />
      </geometry>
    </collision>
  </link>
  <joint name="rear_left_wheel_joint" type="continuous">
    <origin
      xyz="-0.1 0.01 0.09"
      rpy="1.5708 0 0" />
    <parent link="base_link" />
    <child link="rear_left_wheel_link" />
    <axis xyz="-1 0 0" />
    <dynamics damping="0.1" friction="1.0" />
  </joint>

  <link name="rear_right_wheel_link">
    <inertial>
      <origin
        xyz="-0.175 4.72492608288855E-05 9.01686700283122E-06"
        rpy="0 0 0" />
      <mass value="0.379124506048444" />
      <inertia
        ixx="0.00135623331658277"
        ixy="-2.05858146537997E-08"
        ixz="2.75425144310775E-07"
        iyy="0.00074553860560749"
        iyz="-2.05160697747808E-08"
        izz="0.000744863292198173" />
    </inertial>
    <visual>
      <origin
        xyz="-0.165 0 0"
        rpy="0 1.57 0" />
      <geometry>
        <cylinder radius="${wheel_radius}" length="${wheel_length}" />
      </geometry>
      <material name="">
        <color rgba="0.792156862745098 0.819607843137255 0.933333333333333 1" />
      </material>
    </visual>
    <collision>
      <origin
        xyz="-0.165 0 0"
        rpy="0 1.57 0" />
      <geometry>
        <cylinder radius="${wheel_radius}" length="${wheel_length}" />
      </geometry>
    </collision>
  </link>
  <joint name="rear_right_wheel_joint" type="continuous">
    <origin
      xyz="0.1 0.01 0.09"
      rpy="0 0 3.1416" />
    <parent link="base_link" />
    <child link="rear_right_wheel_link" />
    <axis xyz="1 0 0" />
    <dynamics damping="0.1" friction="1.0" />
  </joint>
</robot>