<?xml version="1.0" encoding="utf-8"?>
<!-- This URDF was automatically created by SolidWorks to URDF Exporter! Originally created by
Stephen Brawner (brawner@gmail.com) 
     Commit Version: 1.5.1-0-g916b5db  Build Version: 1.5.7152.31018
     For more information, please see http://wiki.ros.org/sw_urdf_exporter -->

<robot name="segwayrmp_description" xmlns:xacro="http://ros.org/wiki/xacro">
  <!-- Define robot constants -->
  <xacro:property name="base_width" value="0.598" />
  <xacro:property name="base_length" value="0.672" />
  <xacro:property name="base_height" value="0.280" />

  <!-- Dummy root link -->
  <link name="world_link" />

  <!-- Robot Base -->
  <link name="base_link">
    <inertial>
      <origin
        xyz="0 0.23 0.19"
        rpy="0 0 0" />
      <mass
        value="2.42397545608915" />
        <inertia ixx="0.0296962022350776" ixy="0" ixz="0"
        iyy="0.00646533575042488" iyz="0" izz="0.0331663553221158" />
    </inertial>
    <visual>
      <origin xyz="0 0.24 0.31" rpy="0 0 0" />
      <geometry>
        <mesh filename="package://segwayrmp_description/meshes/chejia_link.STL" />
      </geometry>
      <material name="">
        <color rgba="0.792156862745098 0.819607843137255 0.933333333333333 1" />
      </material>
    </visual>
    <collision>
      <origin xyz="0 0.24 0.31" rpy="0 0 0" />
      <geometry>
        <mesh filename="package://segwayrmp_description/meshes/chejia_link.STL" />
      </geometry>
    </collision>
  </link>

  <!-- Fixed joint between world_link and base_link -->
  <joint name="world_joint" type="fixed">
    <parent link="world_link" />
    <child link="base_link" />
    <origin xyz="0 0 0" rpy="0 0 0" />
  </joint>

  <!-- Robot Footprint -->
  <link name="base_footprint" />

  <joint name="base_joint" type="fixed">
    <parent link="base_link" />
    <child link="base_footprint" />
    <origin xyz="0.0 0.26 0" rpy="0 0 0" />
  </joint>

  <link name="FrontPivot_Link">
    <inertial>
      <origin
        xyz="0.00350625991709064 0 0"
        rpy="0 0 0" />
      <mass
        value="0.636763996187421" />
      <inertia
        ixx="0.000522373966033037"
        ixy="6.88842321153043E-11"
        ixz="-2.55687287488004E-10"
        iyy="0.000692728712644784"
        iyz="1.31394242797586E-12"
        izz="0.000643891365515844" />
    </inertial>
    <visual>
      <origin xyz="0.0 0.16 0.22" rpy="0 0 0" />
      <geometry>
        <mesh
          filename="package://segwayrmp_description/meshes/zhuanxiangjia_Link.STL" />
      </geometry>
      <material name="">
        <color rgba="0.792156862745098 0.819607843137255 0.933333333333333 1" />
      </material>
    </visual>
    <collision>
      <origin xyz="0 0.16 0.22" rpy="0 0 0" />
      <geometry>
        <mesh filename="package://segwayrmp_description/meshes/zhuanxiangjia_Link.STL" />
      </geometry>
    </collision>
  </link>
  <joint name="FrontPivot_joint" type="revolute">
    <origin xyz="0 0.46 0.15" rpy="1.5708 0 0" />
    <parent link="base_link" />
    <child link="FrontPivot_Link" />
    <axis xyz="0 -1 0" />
    <limit
      lower="-0.36"
      upper="0.36"
      effort="0"
      velocity="0" />
  </joint>
  <link
    name="LeftFrontWheel_Link">
    <inertial>
      <origin
        xyz="-0.21 0 0"
        rpy="0 0 0" />
      <mass
        value="0.379124506048444" />
      <inertia
        ixx="0.00135623331658277"
        ixy="-2.05858146537997E-08"
        ixz="2.75425144310775E-07"
        iyy="0.00074553860560749"
        iyz="-2.05160697747808E-08"
        izz="0.000744863292198173" />
    </inertial>
    <visual>
      <origin
        xyz="0.015 0 0"
        rpy="0 0 0" />
      <geometry>
        <mesh
          filename="package://segwayrmp_description/meshes/zuohoulun_Link.STL" />
      </geometry>
      <material
        name="">
        <color
          rgba="0.792156862745098 0.819607843137255 0.933333333333333 1" />
      </material>
    </visual>
    <collision>
      <origin
        xyz="0.015 0 0"
        rpy="0 0 0" />
      <geometry>
        <mesh
          filename="package://segwayrmp_description/meshes/zuohoulun_Link.STL" />
      </geometry>
    </collision>
  </link>
  <joint
    name="LeftFrontWheel_joint"
    type="continuous">
    <origin
      xyz="-0.092435 -0.06 -0.02"
      rpy="2.9877 0 0" />
    <parent
      link="FrontPivot_Link" />
    <child
      link="LeftFrontWheel_Link" />
    <axis
      xyz="1 0 0" />
  </joint>
  <link
    name="RightFrontWheel_Link">
    <inertial>
      <origin
        xyz="-0.21 0.01 0"
        rpy="0 0 0" />
      <mass
        value="0.37912408551256" />
      <inertia
        ixx="0.0013562336762928"
        ixy="-2.05946493125457E-08"
        ixz="2.75615782692675E-07"
        iyy="0.0007455386716045"
        iyz="-2.12571382999838E-08"
        izz="0.000744862395561634" />
    </inertial>
    <visual>
      <origin
        xyz="0.015 0 0"
        rpy="0 0 0" />
      <geometry>
        <mesh
          filename="package://segwayrmp_description/meshes/zuohoulun_Link.STL" />
      </geometry>
      <material
        name="">
        <color
          rgba="0.792156862745098 0.819607843137255 0.933333333333333 1" />
      </material>
    </visual>
    <collision>
      <origin
        xyz="0.015 0 0"
        rpy="0 0 0" />
      <geometry>
        <mesh
          filename="package://segwayrmp_description/meshes/zuohoulun_Link.STL" />
      </geometry>
    </collision>
  </link>
  <joint
    name="RightFrontWheel_joint"
    type="continuous">
    <origin
      xyz="0.099447 -0.06 0"
      rpy="-1.6671 0 3.1416" />
    <parent
      link="FrontPivot_Link" />
    <child
      link="RightFrontWheel_Link" />
    <axis
      xyz="1 0 0" />
  </joint>
  <link
    name="LeftRearWheel_Link">
    <inertial>
      <origin
        xyz="-0.205721407122161 4.72112875317676E-05 9.00201436271342E-06"
        rpy="0 0 0" />
      <mass
        value="0.634779873374433" />
      <inertia
        ixx="0.00181854534335576"
        ixy="3.33041385279325E-07"
        ixz="-2.8378478388468E-07"
        iyy="0.00101390067982028"
        iyz="-5.2299696505564E-09"
        izz="0.00101270577373137" />
    </inertial>
    <visual>
      <origin
        xyz="0.03 0 0"
        rpy="0 0 0" />
      <geometry>
        <mesh
          filename="package://segwayrmp_description/meshes/zuohoulun_Link.STL" />
      </geometry>
      <material
        name="">
        <color
          rgba="0.792156862745098 0.819607843137255 0.933333333333333 1" />
      </material>
    </visual>
    <collision>
      <origin
        xyz="0.03 0 0"
        rpy="0 0 0" />
      <geometry>
        <mesh
          filename="package://segwayrmp_description/meshes/zuohoulun_Link.STL" />
      </geometry>
    </collision>
  </link>
  <joint
    name="LeftRearWheel_joint"
    type="continuous">
    <origin
      xyz="-0.1 0.01 0.09"
      rpy="1.5708 0 0" />
    <parent
      link="base_link" />
    <child
      link="LeftRearWheel_Link" />
    <axis
      xyz="1 0 0" />
  </joint>
  <link
    name="RightRearWheel_Link">
    <inertial>
      <origin
        xyz="-0.205721415016193 4.72492608288855E-05 9.01686700283122E-06"
        rpy="0 0 0" />
      <mass
        value="0.634778552429949" />
      <inertia
        ixx="0.00181854505148151"
        ixy="3.32515010548019E-07"
        ixz="-2.83394847813244E-07"
        iyy="0.00101390105479182"
        iyz="-5.03852728516005E-09"
        izz="0.00101270465329001" />
    </inertial>
    <visual>
      <origin
        xyz="0.03 0 0"
        rpy="0 0 0" />
      <geometry>
        <mesh
          filename="package://segwayrmp_description/meshes/zuohoulun_Link.STL" />
      </geometry>
      <material
        name="">
        <color
          rgba="0.792156862745098 0.819607843137255 0.933333333333333 1" />
      </material>
    </visual>
    <collision>
      <origin
        xyz="0.03 0 0"
        rpy="0 0 0" />
      <geometry>
        <mesh
          filename="package://segwayrmp_description/meshes/zuohoulun_Link.STL" />
      </geometry>
    </collision>
  </link>
  <joint
    name="RightRearWheel_joint"
    type="continuous">
    <origin
      xyz="0.1 0.01 0.09"
      rpy="0.17453 0 -3.1416" />
    <parent
      link="base_link" />
    <child
      link="RightRearWheel_Link" />
    <axis
      xyz="1 0 0" />
  </joint>
</robot>